<?xml version="1.0" encoding="UTF-8"?>
<testsuite name="Tests" tests="6" skipped="0" failures="5" errors="0" timestamp="2019-12-31T04:56:46" hostname="DESKTOP-J7I54DS" time="0.021">
  <properties/>
  <testcase name="testPeekWhenStackIsPopulated" classname="Tests" time="0.007">
    <failure message="java.lang.ArrayIndexOutOfBoundsException: Index 1 out of bounds for length 1" type="java.lang.ArrayIndexOutOfBoundsException">java.lang.ArrayIndexOutOfBoundsException: Index 1 out of bounds for length 1
	at Task.push(Task.java:19)
	at Tests.testPeekWhenStackIsPopulated(Tests.java:54)
	at java.base/jdk.internal.reflect.NativeMethodAccessorImpl.invoke0(Native Method)
	at java.base/jdk.internal.reflect.NativeMethodAccessorImpl.invoke(NativeMethodAccessorImpl.java:62)
	at java.base/jdk.internal.reflect.DelegatingMethodAccessorImpl.invoke(DelegatingMethodAccessorImpl.java:43)
	at java.base/java.lang.reflect.Method.invoke(Method.java:566)
	at org.junit.runners.model.FrameworkMethod$1.runReflectiveCall(FrameworkMethod.java:50)
	at org.junit.internal.runners.model.ReflectiveCallable.run(ReflectiveCallable.java:12)
	at org.junit.runners.model.FrameworkMethod.invokeExplosively(FrameworkMethod.java:47)
	at org.junit.internal.runners.statements.InvokeMethod.evaluate(InvokeMethod.java:17)
	at org.junit.internal.runners.statements.RunAfters.evaluate(RunAfters.java:27)
	at org.junit.internal.runners.statements.FailOnTimeout$CallableStatement.call(FailOnTimeout.java:298)
	at org.junit.internal.runners.statements.FailOnTimeout$CallableStatement.call(FailOnTimeout.java:292)
	at java.base/java.util.concurrent.FutureTask.run(FutureTask.java:264)
	at java.base/java.lang.Thread.run(Thread.java:834)
</failure>
  </testcase>
  <testcase name="testPush" classname="Tests" time="0.003">
    <failure message="java.lang.ArrayIndexOutOfBoundsException: Index 1 out of bounds for length 1" type="java.lang.ArrayIndexOutOfBoundsException">java.lang.ArrayIndexOutOfBoundsException: Index 1 out of bounds for length 1
	at Task.push(Task.java:19)
	at Tests.testPush(Tests.java:31)
	at java.base/jdk.internal.reflect.NativeMethodAccessorImpl.invoke0(Native Method)
	at java.base/jdk.internal.reflect.NativeMethodAccessorImpl.invoke(NativeMethodAccessorImpl.java:62)
	at java.base/jdk.internal.reflect.DelegatingMethodAccessorImpl.invoke(DelegatingMethodAccessorImpl.java:43)
	at java.base/java.lang.reflect.Method.invoke(Method.java:566)
	at org.junit.runners.model.FrameworkMethod$1.runReflectiveCall(FrameworkMethod.java:50)
	at org.junit.internal.runners.model.ReflectiveCallable.run(ReflectiveCallable.java:12)
	at org.junit.runners.model.FrameworkMethod.invokeExplosively(FrameworkMethod.java:47)
	at org.junit.internal.runners.statements.InvokeMethod.evaluate(InvokeMethod.java:17)
	at org.junit.internal.runners.statements.RunAfters.evaluate(RunAfters.java:27)
	at org.junit.internal.runners.statements.FailOnTimeout$CallableStatement.call(FailOnTimeout.java:298)
	at org.junit.internal.runners.statements.FailOnTimeout$CallableStatement.call(FailOnTimeout.java:292)
	at java.base/java.util.concurrent.FutureTask.run(FutureTask.java:264)
	at java.base/java.lang.Thread.run(Thread.java:834)
</failure>
  </testcase>
  <testcase name="testSize" classname="Tests" time="0.002"/>
  <testcase name="testPopWhenStackIsEmpty" classname="Tests" time="0.002">
    <failure message="java.lang.Exception: Unexpected exception, expected&lt;java.util.EmptyStackException&gt; but was&lt;java.lang.ArrayIndexOutOfBoundsException&gt;" type="java.lang.Exception">java.lang.Exception: Unexpected exception, expected&lt;java.util.EmptyStackException&gt; but was&lt;java.lang.ArrayIndexOutOfBoundsException&gt;
	at org.junit.internal.runners.statements.ExpectException.evaluate(ExpectException.java:28)
	at org.junit.internal.runners.statements.RunAfters.evaluate(RunAfters.java:27)
	at org.junit.internal.runners.statements.FailOnTimeout$CallableStatement.call(FailOnTimeout.java:298)
	at org.junit.internal.runners.statements.FailOnTimeout$CallableStatement.call(FailOnTimeout.java:292)
	at java.base/java.util.concurrent.FutureTask.run(FutureTask.java:264)
	at java.base/java.lang.Thread.run(Thread.java:834)
Caused by: java.lang.ArrayIndexOutOfBoundsException: Index 0 out of bounds for length 0
	at Task.pop(Task.java:28)
	at Tests.testPopWhenStackIsEmpty(Tests.java:66)
	at java.base/jdk.internal.reflect.NativeMethodAccessorImpl.invoke0(Native Method)
	at java.base/jdk.internal.reflect.NativeMethodAccessorImpl.invoke(NativeMethodAccessorImpl.java:62)
	at java.base/jdk.internal.reflect.DelegatingMethodAccessorImpl.invoke(DelegatingMethodAccessorImpl.java:43)
	at java.base/java.lang.reflect.Method.invoke(Method.java:566)
	at org.junit.runners.model.FrameworkMethod$1.runReflectiveCall(FrameworkMethod.java:50)
	at org.junit.internal.runners.model.ReflectiveCallable.run(ReflectiveCallable.java:12)
	at org.junit.runners.model.FrameworkMethod.invokeExplosively(FrameworkMethod.java:47)
	at org.junit.internal.runners.statements.InvokeMethod.evaluate(InvokeMethod.java:17)
	at org.junit.internal.runners.statements.ExpectException.evaluate(ExpectException.java:19)
	... 5 more
</failure>
  </testcase>
  <testcase name="testPopWhenStackIsPopulated" classname="Tests" time="0.003">
    <failure message="java.lang.ArrayIndexOutOfBoundsException: Index 1 out of bounds for length 1" type="java.lang.ArrayIndexOutOfBoundsException">java.lang.ArrayIndexOutOfBoundsException: Index 1 out of bounds for length 1
	at Task.push(Task.java:19)
	at Tests.testPopWhenStackIsPopulated(Tests.java:42)
	at java.base/jdk.internal.reflect.NativeMethodAccessorImpl.invoke0(Native Method)
	at java.base/jdk.internal.reflect.NativeMethodAccessorImpl.invoke(NativeMethodAccessorImpl.java:62)
	at java.base/jdk.internal.reflect.DelegatingMethodAccessorImpl.invoke(DelegatingMethodAccessorImpl.java:43)
	at java.base/java.lang.reflect.Method.invoke(Method.java:566)
	at org.junit.runners.model.FrameworkMethod$1.runReflectiveCall(FrameworkMethod.java:50)
	at org.junit.internal.runners.model.ReflectiveCallable.run(ReflectiveCallable.java:12)
	at org.junit.runners.model.FrameworkMethod.invokeExplosively(FrameworkMethod.java:47)
	at org.junit.internal.runners.statements.InvokeMethod.evaluate(InvokeMethod.java:17)
	at org.junit.internal.runners.statements.RunAfters.evaluate(RunAfters.java:27)
	at org.junit.internal.runners.statements.FailOnTimeout$CallableStatement.call(FailOnTimeout.java:298)
	at org.junit.internal.runners.statements.FailOnTimeout$CallableStatement.call(FailOnTimeout.java:292)
	at java.base/java.util.concurrent.FutureTask.run(FutureTask.java:264)
	at java.base/java.lang.Thread.run(Thread.java:834)
</failure>
  </testcase>
  <testcase name="testPeekWhenStackIsEmpty" classname="Tests" time="0.003">
    <failure message="java.lang.Exception: Unexpected exception, expected&lt;java.util.EmptyStackException&gt; but was&lt;java.lang.ArrayIndexOutOfBoundsException&gt;" type="java.lang.Exception">java.lang.Exception: Unexpected exception, expected&lt;java.util.EmptyStackException&gt; but was&lt;java.lang.ArrayIndexOutOfBoundsException&gt;
	at org.junit.internal.runners.statements.ExpectException.evaluate(ExpectException.java:28)
	at org.junit.internal.runners.statements.RunAfters.evaluate(RunAfters.java:27)
	at org.junit.internal.runners.statements.FailOnTimeout$CallableStatement.call(FailOnTimeout.java:298)
	at org.junit.internal.runners.statements.FailOnTimeout$CallableStatement.call(FailOnTimeout.java:292)
	at java.base/java.util.concurrent.FutureTask.run(FutureTask.java:264)
	at java.base/java.lang.Thread.run(Thread.java:834)
Caused by: java.lang.ArrayIndexOutOfBoundsException: Index 0 out of bounds for length 0
	at Task.peek(Task.java:39)
	at Tests.testPeekWhenStackIsEmpty(Tests.java:72)
	at java.base/jdk.internal.reflect.NativeMethodAccessorImpl.invoke0(Native Method)
	at java.base/jdk.internal.reflect.NativeMethodAccessorImpl.invoke(NativeMethodAccessorImpl.java:62)
	at java.base/jdk.internal.reflect.DelegatingMethodAccessorImpl.invoke(DelegatingMethodAccessorImpl.java:43)
	at java.base/java.lang.reflect.Method.invoke(Method.java:566)
	at org.junit.runners.model.FrameworkMethod$1.runReflectiveCall(FrameworkMethod.java:50)
	at org.junit.internal.runners.model.ReflectiveCallable.run(ReflectiveCallable.java:12)
	at org.junit.runners.model.FrameworkMethod.invokeExplosively(FrameworkMethod.java:47)
	at org.junit.internal.runners.statements.InvokeMethod.evaluate(InvokeMethod.java:17)
	at org.junit.internal.runners.statements.ExpectException.evaluate(ExpectException.java:19)
	... 5 more
</failure>
  </testcase>
  <system-out><![CDATA[]]></system-out>
  <system-err><![CDATA[]]></system-err>
</testsuite>
