<?xml version="1.0" encoding="UTF-8"?>
<testsuite name="EmployeeTest" tests="5" skipped="0" failures="4" errors="0" timestamp="2019-12-30T21:09:22" hostname="DESKTOP-5VVSC2K" time="0.012">
  <properties/>
  <testcase name="testToEnsureThatEmployeeCannotBeInstantiatedWithNegativeId" classname="EmployeeTest" time="0.004">
    <failure message="java.lang.AssertionError: Should not be able to instantiate employee with a negative id expected:&lt;0&gt; but was:&lt;-1&gt;" type="java.lang.AssertionError">java.lang.AssertionError: Should not be able to instantiate employee with a negative id expected:&lt;0&gt; but was:&lt;-1&gt;
	at org.junit.Assert.fail(Assert.java:88)
	at org.junit.Assert.failNotEquals(Assert.java:834)
	at org.junit.Assert.assertEquals(Assert.java:645)
	at EmployeeTest.testToEnsureThatEmployeeCannotBeInstantiatedWithNegativeId(EmployeeTest.java:50)
	at java.base/jdk.internal.reflect.NativeMethodAccessorImpl.invoke0(Native Method)
	at java.base/jdk.internal.reflect.NativeMethodAccessorImpl.invoke(NativeMethodAccessorImpl.java:62)
	at java.base/jdk.internal.reflect.DelegatingMethodAccessorImpl.invoke(DelegatingMethodAccessorImpl.java:43)
	at java.base/java.lang.reflect.Method.invoke(Method.java:566)
	at org.junit.runners.model.FrameworkMethod$1.runReflectiveCall(FrameworkMethod.java:50)
	at org.junit.internal.runners.model.ReflectiveCallable.run(ReflectiveCallable.java:12)
	at org.junit.runners.model.FrameworkMethod.invokeExplosively(FrameworkMethod.java:47)
	at org.junit.internal.runners.statements.InvokeMethod.evaluate(InvokeMethod.java:17)
	at org.junit.internal.runners.statements.RunBefores.evaluate(RunBefores.java:26)
	at org.junit.internal.runners.statements.RunAfters.evaluate(RunAfters.java:27)
	at org.junit.rules.ExpectedException$ExpectedExceptionStatement.evaluate(ExpectedException.java:239)
	at org.junit.internal.runners.statements.FailOnTimeout$CallableStatement.call(FailOnTimeout.java:298)
	at org.junit.internal.runners.statements.FailOnTimeout$CallableStatement.call(FailOnTimeout.java:292)
	at java.base/java.util.concurrent.FutureTask.run(FutureTask.java:264)
	at java.base/java.lang.Thread.run(Thread.java:834)
</failure>
  </testcase>
  <testcase name="testToEnsureThatEmployeeCannotBeInstantiatedWithNegativeSalary" classname="EmployeeTest" time="0.004">
    <failure message="java.lang.AssertionError: Should not be able to instantiate employee with a negative salary expected:&lt;0.0&gt; but was:&lt;-90000.0&gt;" type="java.lang.AssertionError">java.lang.AssertionError: Should not be able to instantiate employee with a negative salary expected:&lt;0.0&gt; but was:&lt;-90000.0&gt;
	at org.junit.Assert.fail(Assert.java:88)
	at org.junit.Assert.failNotEquals(Assert.java:834)
	at org.junit.Assert.assertEquals(Assert.java:553)
	at EmployeeTest.testToEnsureThatEmployeeCannotBeInstantiatedWithNegativeSalary(EmployeeTest.java:56)
	at java.base/jdk.internal.reflect.NativeMethodAccessorImpl.invoke0(Native Method)
	at java.base/jdk.internal.reflect.NativeMethodAccessorImpl.invoke(NativeMethodAccessorImpl.java:62)
	at java.base/jdk.internal.reflect.DelegatingMethodAccessorImpl.invoke(DelegatingMethodAccessorImpl.java:43)
	at java.base/java.lang.reflect.Method.invoke(Method.java:566)
	at org.junit.runners.model.FrameworkMethod$1.runReflectiveCall(FrameworkMethod.java:50)
	at org.junit.internal.runners.model.ReflectiveCallable.run(ReflectiveCallable.java:12)
	at org.junit.runners.model.FrameworkMethod.invokeExplosively(FrameworkMethod.java:47)
	at org.junit.internal.runners.statements.InvokeMethod.evaluate(InvokeMethod.java:17)
	at org.junit.internal.runners.statements.RunBefores.evaluate(RunBefores.java:26)
	at org.junit.internal.runners.statements.RunAfters.evaluate(RunAfters.java:27)
	at org.junit.rules.ExpectedException$ExpectedExceptionStatement.evaluate(ExpectedException.java:239)
	at org.junit.internal.runners.statements.FailOnTimeout$CallableStatement.call(FailOnTimeout.java:298)
	at org.junit.internal.runners.statements.FailOnTimeout$CallableStatement.call(FailOnTimeout.java:292)
	at java.base/java.util.concurrent.FutureTask.run(FutureTask.java:264)
	at java.base/java.lang.Thread.run(Thread.java:834)
</failure>
  </testcase>
  <testcase name="testIfEmployeeIsProperPojo" classname="EmployeeTest" time="0.001"/>
  <testcase name="testToEnsureThatSalaryCannotBeSetToNegativeNumber" classname="EmployeeTest" time="0.001">
    <failure message="java.lang.AssertionError: Should not be able to set salary to negative value expected:&lt;90000.0&gt; but was:&lt;-100000.0&gt;" type="java.lang.AssertionError">java.lang.AssertionError: Should not be able to set salary to negative value expected:&lt;90000.0&gt; but was:&lt;-100000.0&gt;
	at org.junit.Assert.fail(Assert.java:88)
	at org.junit.Assert.failNotEquals(Assert.java:834)
	at org.junit.Assert.assertEquals(Assert.java:553)
	at EmployeeTest.testToEnsureThatSalaryCannotBeSetToNegativeNumber(EmployeeTest.java:71)
	at java.base/jdk.internal.reflect.NativeMethodAccessorImpl.invoke0(Native Method)
	at java.base/jdk.internal.reflect.NativeMethodAccessorImpl.invoke(NativeMethodAccessorImpl.java:62)
	at java.base/jdk.internal.reflect.DelegatingMethodAccessorImpl.invoke(DelegatingMethodAccessorImpl.java:43)
	at java.base/java.lang.reflect.Method.invoke(Method.java:566)
	at org.junit.runners.model.FrameworkMethod$1.runReflectiveCall(FrameworkMethod.java:50)
	at org.junit.internal.runners.model.ReflectiveCallable.run(ReflectiveCallable.java:12)
	at org.junit.runners.model.FrameworkMethod.invokeExplosively(FrameworkMethod.java:47)
	at org.junit.internal.runners.statements.InvokeMethod.evaluate(InvokeMethod.java:17)
	at org.junit.internal.runners.statements.RunBefores.evaluate(RunBefores.java:26)
	at org.junit.internal.runners.statements.RunAfters.evaluate(RunAfters.java:27)
	at org.junit.rules.ExpectedException$ExpectedExceptionStatement.evaluate(ExpectedException.java:239)
	at org.junit.internal.runners.statements.FailOnTimeout$CallableStatement.call(FailOnTimeout.java:298)
	at org.junit.internal.runners.statements.FailOnTimeout$CallableStatement.call(FailOnTimeout.java:292)
	at java.base/java.util.concurrent.FutureTask.run(FutureTask.java:264)
	at java.base/java.lang.Thread.run(Thread.java:834)
</failure>
  </testcase>
  <testcase name="testToEnsureThatIdCannotBeSetToNegativeNumber" classname="EmployeeTest" time="0.002">
    <failure message="java.lang.AssertionError: Should not be able to set id to negative value expected:&lt;1&gt; but was:&lt;-1&gt;" type="java.lang.AssertionError">java.lang.AssertionError: Should not be able to set id to negative value expected:&lt;1&gt; but was:&lt;-1&gt;
	at org.junit.Assert.fail(Assert.java:88)
	at org.junit.Assert.failNotEquals(Assert.java:834)
	at org.junit.Assert.assertEquals(Assert.java:645)
	at EmployeeTest.testToEnsureThatIdCannotBeSetToNegativeNumber(EmployeeTest.java:64)
	at java.base/jdk.internal.reflect.NativeMethodAccessorImpl.invoke0(Native Method)
	at java.base/jdk.internal.reflect.NativeMethodAccessorImpl.invoke(NativeMethodAccessorImpl.java:62)
	at java.base/jdk.internal.reflect.DelegatingMethodAccessorImpl.invoke(DelegatingMethodAccessorImpl.java:43)
	at java.base/java.lang.reflect.Method.invoke(Method.java:566)
	at org.junit.runners.model.FrameworkMethod$1.runReflectiveCall(FrameworkMethod.java:50)
	at org.junit.internal.runners.model.ReflectiveCallable.run(ReflectiveCallable.java:12)
	at org.junit.runners.model.FrameworkMethod.invokeExplosively(FrameworkMethod.java:47)
	at org.junit.internal.runners.statements.InvokeMethod.evaluate(InvokeMethod.java:17)
	at org.junit.internal.runners.statements.RunBefores.evaluate(RunBefores.java:26)
	at org.junit.internal.runners.statements.RunAfters.evaluate(RunAfters.java:27)
	at org.junit.rules.ExpectedException$ExpectedExceptionStatement.evaluate(ExpectedException.java:239)
	at org.junit.internal.runners.statements.FailOnTimeout$CallableStatement.call(FailOnTimeout.java:298)
	at org.junit.internal.runners.statements.FailOnTimeout$CallableStatement.call(FailOnTimeout.java:292)
	at java.base/java.util.concurrent.FutureTask.run(FutureTask.java:264)
	at java.base/java.lang.Thread.run(Thread.java:834)
</failure>
  </testcase>
  <system-out><![CDATA[]]></system-out>
  <system-err><![CDATA[]]></system-err>
</testsuite>
